Workbook

Sheet Read me
A1: DAMM v1.5 — the model this application runs
A3: Model | B3: DAMM v1.5
A4: Status | B4: Live scoring workbook; diagnostic package workflow
A5: Assessment year | B5: 2026
A6: Extracted from | B6: DAMM v1.5 Scoring Workbook — Egypt worked example.xlsx
A7: Indicators | B7: =COUNTA(Indicators!A2:A200) -> 102
A8: Pillars | B8: =COUNTIF(Pillars!$C$2:$C$50,"Context")+COUNTIF(Pillars!$C$2:$C$50,"Capability")+COUNTIF(Pillars!$C$2:$C$50,"Ecosystem")+COUNTIF(Pillars!$C$2:$C$50,"Outcome") -> 8
A9: Core gates | B9: =COUNTA('Core gates'!A2:A50) -> 14
A10: Process steps | B10: =COUNTA('Process ladder'!A2:A50) -> 4
A12: Prohibitions wired into the model
A13: 1 | B13: No cross-country ranking
A14: 2 | B14: No DAMM stage used as PDO indicator, DLI, or disbursement condition
A15: 3 | B15: No automatic financing, procurement, vendor, or technology decisions from the diagnostic
A16: 4 | B16: No stage claimed publicly before human review by the TTL and steering committee
A18: Sheets
A19: Indicators | B19: All indicators: pillar, role, method, direction, core-gate flag, staleness limit, and the value thresholds for levels 2-5.
A20: Qualitative anchors | B20: The written L1-L5 anchor text. Qualitative indicators are scored against these words, not against a number.
A21: Pillars | B21: Pillars with role and weight. C0 is a context profile and is never aggregated into a score.
A22: Core gates | B22: Prerequisite indicators. One at Level 1 caps the stage at 1; one unmeasured suppresses the stage entirely.
A23: Scoring rules | B23: Bands, coverage gates, stage floors, the leapfrog-fragility threshold and confidence weights.
A24: Process ladder | B24: The four steps: populate, score evidence quality, compile the diagnostic package, draft the roadmap.
A25: Glossary | B25: CMS, EMS, OES and the rest, defined as the model defines them.
A27: Reading the thresholds
B28: Where Direction is Higher, a value at or above the L5 threshold scores 5, at or above L4 scores 4, and so on; below the L2 threshold scores 1.
B29: Where Direction is Lower, the comparison reverses: at or below the L5 threshold scores 5.
B30: Where Direction is N/A there are no thresholds. The indicator is either a qualitative capability assessed against the anchor text, or a context profile that is never scored.
B31: Source: model_v1_5.json in the application repository, extracted from DAMM v1.5 Scoring Workbook — Egypt worked example.xlsx.

Sheet Indicators
A1: ID | B1: Indicator | C1: Pillar | D1: Pillar name | E1: Role | F1: Source | G1: Method | H1: Direction | I1: Core gate | J1: Max age (yrs) | K1: L2 | L1: L3 | M1: L4 | N1: L5 | O1: Status
A2: 1.1 | B2: Agriculture value added per worker (constant 2015 USD) | C2: C0 | D2: C0: Agricultural context & need | E2: Context | F2: Global | G2: Context profile (not aggregated) | H2: N/A | J2: 3 | O2: Context only
A3: 1.2 | B3: Cereal yield (kg per hectare) | C3: C0 | D3: C0: Agricultural context & need | E3: Context | F3: Global | G3: Context profile (not aggregated) | H3: N/A | J3: 3 | O3: Context only
A4: 1.3 | B4: Employment in agriculture (% of total employment) | C4: C0 | D4: C0: Agricultural context & need | E4: Context | F4: Global | G4: Context profile (not aggregated) | H4: N/A | J4: 3 | O4: Context only
A5: 1.4 | B5: Food production index (2014-2016 = 100) | C5: C0 | D5: C0: Agricultural context & need | E5: Context | F5: Global | G5: Context profile (not aggregated) | H5: N/A | J5: 3 | O5: Context only
A6: 1.5 | B6: Post-harvest loss rate (%) | C6: C0 | D6: C0: Agricultural context & need | E6: Context | F6: Local | G6: Context profile (not aggregated) | H6: N/A | J6: 2 | O6: Context only
A7: 1.6 | B7: Smallholder access to formal markets (%) | C7: C0 | D7: C0: Agricultural context & need | E7: Context | F7: Local | G7: Context profile (not aggregated) | H7: N/A | J7: 2 | O7: Context only
A8: 1.7 | B8: Agricultural credit access (% of farmers) | C8: C0 | D8: C0: Agricultural context & need | E8: Context | F8: Local | G8: Context profile (not aggregated) | H8: N/A | J8: 2 | O8: Context only
A9: 1.8 | B9: Farmers using climate-smart/sustainable practices (%) | C9: C0 | D9: C0: Agricultural context & need | E9: Context | F9: Local | G9: Context profile (not aggregated) | H9: N/A | J9: 2 | O9: Context only
A10: 1.9 | B10: National innovation/extension programs with digital component | C10: C4 | D10: C4: Human & institutional capacity | E10: Capability | F10: Local | G10: Qualitative (capability) | H10: N/A | J10: 2 | O10: Qualitative
A11: 2.1 | B11: Rural population covered by at least 3G (%) | C11: C1 | D11: C1: Connectivity & affordable access | E11: Capability | F11: Global | G11: Quantitative threshold | H11: Higher | I11: YES | J11: 3 | K11: 20 | L11: 40 | M11: 60 | N11: 80 | O11: Numeric threshold
A12: 2.2 | B12: Rural population covered by at least 4G (%) | C12: C1 | D12: C1: Connectivity & affordable access | E12: Capability | F12: Global | G12: Quantitative threshold | H12: Higher | J12: 3 | K12: 20 | L12: 40 | M12: 60 | N12: 80 | O12: Numeric threshold
A13: 2.3 | B13: Active mobile broadband subscriptions per 100 inhabitants | C13: C1 | D13: C1: Connectivity & affordable access | E13: Capability | F13: Global | G13: Quantitative threshold | H13: Higher | J13: 3 | K13: 20 | L13: 40 | M13: 70 | N13: 100 | O13: Numeric threshold
A14: 2.4 | B14: Individuals using the Internet (% of population) | C14: C1 | D14: C1: Connectivity & affordable access | E14: Capability | F14: Global | G14: Quantitative threshold | H14: Higher | J14: 3 | K14: 20 | L14: 40 | M14: 60 | N14: 80 | O14: Numeric threshold
A15: 2.5 | B15: Mobile broadband basket price (% GNI per capita) | C15: C1 | D15: C1: Connectivity & affordable access | E15: Capability | F15: Global | G15: Quantitative threshold | H15: Lower | I15: YES | J15: 3 | K15: 10 | L15: 5 | M15: 2 | N15: 1 | O15: Numeric threshold
A16: 2.6 | B16: Adults with mobile phone (% age 15+) | C16: C1 | D16: C1: Connectivity & affordable access | E16: Capability | F16: Global | G16: Quantitative threshold | H16: Higher | J16: 3 | K16: 20 | L16: 40 | M16: 60 | N16: 80 | O16: Numeric threshold
A17: 2.7 | B17: Smartphone ownership among rural/agricultural population (%) | C17: C1 | D17: C1: Connectivity & affordable access | E17: Capability | F17: Local | G17: Quantitative threshold | H17: Higher | J17: 2 | K17: 20 | L17: 40 | M17: 60 | N17: 80 | O17: Numeric threshold
A18: 2.8 | B18: Average mobile data cost in rural areas (USD per GB) | C18: C1 | D18: C1: Connectivity & affordable access | E18: Capability | F18: Local | G18: Quantitative threshold | H18: Lower | J18: 2 | K18: 10 | L18: 5 | M18: 2 | N18: 1 | O18: Numeric threshold
A19: 2.9 | B19: Electricity access in rural areas (%) | C19: C1 | D19: C1: Connectivity & affordable access | E19: Capability | F19: Local | G19: Quantitative threshold | H19: Higher | I19: YES | J19: 2 | K19: 20 | L19: 40 | M19: 60 | N19: 80 | O19: Numeric threshold
A20: 2.10 | B20: Average download speed in agricultural areas (Mbps) | C20: C1 | D20: C1: Connectivity & affordable access | E20: Capability | F20: Local | G20: Quantitative threshold | H20: Higher | J20: 2 | K20: 2 | L20: 5 | M20: 10 | N20: 25 | O20: Numeric threshold
A21: 2.11 | B21: Device financing/subsidy schemes for farmers | C21: C1 | D21: C1: Connectivity & affordable access | E21: Capability | F21: Local | G21: Qualitative (capability) | H21: N/A | J21: 2 | O21: Qualitative
A22: 3.1 | B22: UN E-Government Development Index (EGDI) | C22: C2 | D22: C2: Data infrastructure & DPI | E22: Capability | F22: Global | G22: Quantitative threshold | H22: Higher | J22: 3 | K22: 0.2 | L22: 0.4 | M22: 0.6 | N22: 0.8 | O22: Numeric threshold
A23: 3.2 | B23: Open Data Inventory (ODIN) score | C23: C2 | D23: C2: Data infrastructure & DPI | E23: Capability | F23: Global | G23: Quantitative threshold | H23: Higher | J23: 3 | K23: 20 | L23: 40 | M23: 60 | N23: 80 | O23: Numeric threshold
A24: 3.3 | B24: National farmer registry/database | C24: C2 | D24: C2: Data infrastructure & DPI | E24: Capability | F24: Local | G24: Qualitative (capability) | H24: N/A | I24: YES | J24: 2 | O24: Qualitative
A25: 3.4 | B25: Digital land/plot registration system | C25: C2 | D25: C2: Data infrastructure & DPI | E25: Capability | F25: Local | G25: Qualitative (capability) | H25: N/A | J25: 2 | O25: Qualitative
A26: 3.5 | B26: National agricultural data portal / open data | C26: C2 | D26: C2: Data infrastructure & DPI | E26: Capability | F26: Local | G26: Qualitative (capability) | H26: N/A | J26: 2 | O26: Qualitative
A27: 3.6 | B27: Weather/climate data infrastructure for agriculture | C27: C2 | D27: C2: Data infrastructure & DPI | E27: Capability | F27: Local | G27: Qualitative (capability) | H27: N/A | J27: 2 | O27: Qualitative
A28: 3.7 | B28: Satellite/earth observation data integration capability | C28: C2 | D28: C2: Data infrastructure & DPI | E28: Capability | F28: Local | G28: Qualitative (capability) | H28: N/A | J28: 2 | O28: Qualitative
A29: 3.8 | B29: National soil map/database (digital) | C29: C2 | D29: C2: Data infrastructure & DPI | E29: Capability | F29: Local | G29: Qualitative (capability) | H29: N/A | J29: 2 | O29: Qualitative
A30: 3.9 | B30: Digital advisory platforms reaching >10,000 users | C30: C2 | D30: C2: Data infrastructure & DPI | E30: Capability | F30: Local | G30: Quantitative threshold | H30: Higher | J30: 2 | K30: 20 | L30: 40 | M30: 60 | N30: 80 | O30: Numeric threshold
A31: 3.10 | B31: Digital agricultural market/e-commerce platforms (>5,000 active users) | C31: C2 | D31: C2: Data infrastructure & DPI | E31: Capability | F31: Local | G31: Qualitative (capability) | H31: N/A | J31: 2 | O31: Qualitative
A32: 3.11 | B32: Interoperability standards for agricultural data | C32: C2 | D32: C2: Data infrastructure & DPI | E32: Capability | F32: Local | G32: Qualitative (capability) | H32: N/A | I32: YES | J32: 2 | O32: Qualitative
A33: 3.12 | B33: AI-ready agricultural datasets | C33: C2 | D33: C2: Data infrastructure & DPI | E33: Capability | F33: Local | G33: Qualitative (capability) | H33: N/A | J33: 2 | O33: Qualitative
A34: 3.13 | B34: Machine-readable open agricultural data (share of national ag statistics as open APIs) | C34: C2 | D34: C2: Data infrastructure & DPI | E34: Capability | F34: Local | G34: Quantitative threshold | H34: Higher | J34: 2 | K34: 20 | L34: 40 | M34: 60 | N34: 80 | O34: Numeric threshold
A35: 4.1 | B35: Data protection/privacy law | C35: C3 | D35: C3: Policy, governance & safeguards | E35: Capability | F35: Global | G35: Qualitative (capability) | H35: N/A | I35: YES | J35: 3 | O35: Qualitative
A36: 4.2 | B36: Cybersecurity legal framework (ITU GCI) | C36: C3 | D36: C3: Policy, governance & safeguards | E36: Capability | F36: Global | G36: Quantitative threshold | H36: Higher | I36: YES | J36: 3 | K36: 0.2 | L36: 0.4 | M36: 0.6 | N36: 0.8 | O36: Numeric threshold
A37: 4.3 | B37: Government AI Readiness Index | C37: C3 | D37: C3: Policy, governance & safeguards | E37: Capability | F37: Global | G37: Quantitative threshold | H37: Higher | J37: 3 | K37: 20 | L37: 40 | M37: 60 | N37: 80 | O37: Numeric threshold
A38: 4.4 | B38: National digital agriculture strategy | C38: C3 | D38: C3: Policy, governance & safeguards | E38: Capability | F38: Local | G38: Qualitative (capability) | H38: N/A | J38: 2 | O38: Qualitative
A39: 4.5 | B39: Agricultural data governance framework | C39: C3 | D39: C3: Policy, governance & safeguards | E39: Capability | F39: Local | G39: Qualitative (capability) | H39: N/A | I39: YES | J39: 2 | O39: Qualitative
A40: 4.6 | B40: National AI strategy with agriculture component | C40: C3 | D40: C3: Policy, governance & safeguards | E40: Capability | F40: Local | G40: Qualitative (capability) | H40: N/A | J40: 2 | O40: Qualitative
...

Sheet Qualitative anchors
A1: ID | B1: Indicator | C1: Method | D1: Level 1 | E1: Level 2 | F1: Level 3 | G1: Level 4 | H1: Level 5
A2: 1.1 | B2: Agriculture value added per worker (constant 2015 USD) | C2: Context profile (not aggregated) | D2: Profile the observed level and trend; do not interpret as digital maturity. | E2: Profile only. | F2: Profile only. | G2: Profile only. | H2: Profile only.
A3: 1.2 | B3: Cereal yield (kg per hectare) | C3: Context profile (not aggregated) | D3: Profile the observed level and trend; do not interpret as digital maturity. | E3: Profile only. | F3: Profile only. | G3: Profile only. | H3: Profile only.
A4: 1.3 | B4: Employment in agriculture (% of total employment) | C4: Context profile (not aggregated) | D4: Profile the observed level and trend; do not interpret as digital maturity. | E4: Profile only. | F4: Profile only. | G4: Profile only. | H4: Profile only.
A5: 1.4 | B5: Food production index (2014-2016 = 100) | C5: Context profile (not aggregated) | D5: Profile the observed level and trend; do not interpret as digital maturity. | E5: Profile only. | F5: Profile only. | G5: Profile only. | H5: Profile only.
A6: 1.5 | B6: Post-harvest loss rate (%) | C6: Context profile (not aggregated) | D6: Profile the observed level and trend; do not interpret as digital maturity. | E6: Profile only. | F6: Profile only. | G6: Profile only. | H6: Profile only.
A7: 1.6 | B7: Smallholder access to formal markets (%) | C7: Context profile (not aggregated) | D7: Profile the observed level and trend; do not interpret as digital maturity. | E7: Profile only. | F7: Profile only. | G7: Profile only. | H7: Profile only.
A8: 1.7 | B8: Agricultural credit access (% of farmers) | C8: Context profile (not aggregated) | D8: Profile the observed level and trend; do not interpret as digital maturity. | E8: Profile only. | F8: Profile only. | G8: Profile only. | H8: Profile only.
A9: 1.8 | B9: Farmers using climate-smart/sustainable practices (%) | C9: Context profile (not aggregated) | D9: Profile the observed level and trend; do not interpret as digital maturity. | E9: Profile only. | F9: Profile only. | G9: Profile only. | H9: Profile only.
A10: 1.9 | B10: National innovation/extension programs with digital component | C10: Qualitative (capability) | D10: No credible national innovation/extension programs with digital component capability, or isolated informal activity only. | E10: Pilot or ad hoc national innovation/extension programs with digital component; narrow coverage, unclear ownership or donor dependence. | F10: Operational national innovation/extension programs with digital component with defined ownership and partial coverage; adoption or interoperability gaps remain. | G10: Scaled and funded national innovation/extension programs with digital component, with accountable governance, interoperability and broad use. | H10: Institutionalized, inclusive and resilient national innovation/extension programs with digital component, continuously improved and supported by verified outcomes.
A11: 2.1 | B11: Rural population covered by at least 3G (%) | C11: Quantitative threshold | D11: < 20 | E11: 20 to < 40 | F11: 40 to < 60 | G11: 60 to < 80 | H11: >= 80
A12: 2.2 | B12: Rural population covered by at least 4G (%) | C12: Quantitative threshold | D12: < 20 | E12: 20 to < 40 | F12: 40 to < 60 | G12: 60 to < 80 | H12: >= 80
... A103: 8.17 | B103: Climate advisory reach (% farmers receiving actionable seasonal advisories) | C103: Quantitative threshold | D103: < 20 | E103: 20 to < 40 | F103: 40 to < 60 | G103: 60 to < 80 | H103: ≥ 80

Sheet Pillars
A1: Pillar | B1: Name | C1: Role | D1: Weight | E1: Aggregated | F1: Indicators | G1: Core gates
A2: C0 | B2: Agricultural context & need | C2: Context | E2: No — context only | F2: =COUNTIF(Indicators!$C$2:$C$103,$A2) -> 8 | G2: =COUNTIFS(Indicators!$C$2:$C$103,$A2,Indicators!$I$2:$I$103,"YES") -> 0
A3: C1 | B3: Connectivity & affordable access | C3: Capability | D3: 0.25 | E3: Yes | F3: =COUNTIF(Indicators!$C$2:$C$103,$A3) -> 11 | G3: =COUNTIFS(Indicators!$C$2:$C$103,$A3,Indicators!$I$2:$I$103,"YES") -> 3
A4: C2 | B4: Data infrastructure & DPI | C4: Capability | D4: 0.3 | E4: Yes | F4: =COUNTIF(Indicators!$C$2:$C$103,$A4) -> 13 | G4: =COUNTIFS(Indicators!$C$2:$C$103,$A4,Indicators!$I$2:$I$103,"YES") -> 2
A5: C3 | B5: Policy, governance & safeguards | C5: Capability | D5: 0.25 | E5: Yes | F5: =COUNTIF(Indicators!$C$2:$C$103,$A5) -> 13 | G5: =COUNTIFS(Indicators!$C$2:$C$103,$A5,Indicators!$I$2:$I$103,"YES") -> 4
A6: C4 | B6: Human & institutional capacity | C6: Capability | D6: 0.2 | E6: Yes | F6: =COUNTIF(Indicators!$C$2:$C$103,$A6) -> 14 | G6: =COUNTIFS(Indicators!$C$2:$C$103,$A6,Indicators!$I$2:$I$103,"YES") -> 2
A7: E1 | B7: Innovation & private sector | C7: Ecosystem | D7: 0.7 | E7: Yes | F7: =COUNTIF(Indicators!$C$2:$C$103,$A7) -> 14 | G7: =COUNTIFS(Indicators!$C$2:$C$103,$A7,Indicators!$I$2:$I$103,"YES") -> 1
A8: E2 | B8: Responsible AI & emerging tech | C8: Ecosystem | D8: 0.3 | E8: Yes | F8: =COUNTIF(Indicators!$C$2:$C$103,$A8) -> 12 | G8: =COUNTIFS(Indicators!$C$2:$C$103,$A8,Indicators!$I$2:$I$103,"YES") -> 2
A9: O1 | B9: Inclusion, sustainability & outcomes | C9: Outcome | D9: 1 | E9: Yes | F9: =COUNTIF(Indicators!$C$2:$C$103,$A9) -> 17 | G9: =COUNTIFS(Indicators!$C$2:$C$103,$A9,Indicators!$I$2:$I$103,"YES") -> 0
A10: Total | F10: =SUM(F2:F9) -> 102 | G10: =SUM(G2:G9) -> 14
A12: Weights sum to 1.00 within each role family
A13: Capability (C1-C4) | D13: =SUMIF($C$2:$C$9,"Capability",$D$2:$D$9) -> 1
A14: Ecosystem (E1-E2) | D14: =SUMIF($C$2:$C$9,"Ecosystem",$D$2:$D$9) -> 1
A15: Outcome (O1) | D15: =SUMIF($C$2:$C$9,"Outcome",$D$2:$D$9) -> 1

Sheet Core gates
A1: ID | B1: Indicator | C1: Pillar | D1: Method | E1: Why it gates
A2: 2.1 | B2: Rural population covered by at least 3G (%) | C2: C1 | D2: Quantitative threshold | E2: Prerequisite: at Level 1 it caps the overall stage at Stage 1; unmeasured, it suppresses the stage entirely.
A3: 2.5 | B3: Mobile broadband basket price (% GNI per capita) | C3: C1 | D3: Quantitative threshold | E3: Prerequisite: at Level 1 it caps the overall stage at Stage 1; unmeasured, it suppresses the stage entirely.
A4: 2.9 | B4: Electricity access in rural areas (%) | C4: C1 | D4: Quantitative threshold | E4: Prerequisite: at Level 1 it caps the overall stage at Stage 1; unmeasured, it suppresses the stage entirely.
A5: 3.3 | B5: National farmer registry/database | C5: C2 | D5: Qualitative (capability) | E5: Prerequisite: at Level 1 it caps the overall stage at Stage 1; unmeasured, it suppresses the stage entirely.
A6: 3.11 | B6: Interoperability standards for agricultural data | C6: C2 | D6: Qualitative (capability) | E6: Prerequisite: at Level 1 it caps the overall stage at Stage 1; unmeasured, it suppresses the stage entirely.
A7: 4.1 | B7: Data protection/privacy law | C7: C3 | D7: Qualitative (capability) | E7: Prerequisite: at Level 1 it caps the overall stage at Stage 1; unmeasured, it suppresses the stage entirely.
A8: 4.2 | B8: Cybersecurity legal framework (ITU GCI) | C8: C3 | D8: Quantitative threshold | E8: Prerequisite: at Level 1 it caps the overall stage at Stage 1; unmeasured, it suppresses the stage entirely.
A9: 4.5 | B9: Agricultural data governance framework | C9: C3 | D9: Qualitative (capability) | E9: Prerequisite: at Level 1 it caps the overall stage at Stage 1; unmeasured, it suppresses the stage entirely.
A10: 4.9 | B10: Inter-ministerial coordination mechanism for digital agriculture | C10: C3 | D10: Qualitative (capability) | E10: Prerequisite: at Level 1 it caps the overall stage at Stage 1; unmeasured, it suppresses the stage entirely.
A11: 5.5 | B11: Extension workers trained in digital tools (%) | C11: C4 | D11: Quantitative threshold | E11: Prerequisite: at Level 1 it caps the overall stage at Stage 1; unmeasured, it suppresses the stage entirely.
A12: 5.7 | B12: Dedicated digital/AI units in Ministry of Agriculture | C12: C4 | D12: Qualitative (capability) | E12: Prerequisite: at Level 1 it caps the overall stage at Stage 1; unmeasured, it suppresses the stage entirely.
... A15: 7.12 | B15: Farmer consent and data rights in AI systems | C15: E2 | D15: Qualitative (capability) | E15: Prerequisite: at Level 1 it caps the overall stage at Stage 1; unmeasured, it suppresses the stage entirely.

Sheet Scoring rules
A1: Maturity bands — half-open and mutually exclusive
A2: Level | B2: Band | C2: From (>=) | D2: To (<)
A3: 1 | B3: Nascent | C3: 1 | D3: 1.8
A4: 2 | B4: Emerging | C4: 1.8 | D4: 2.6
A5: 3 | B5: Established | C5: 2.6 | D5: 3.4
A6: 4 | B6: Advanced | C6: 3.4 | D6: 4.2
A7: 5 | B7: Transformative | C7: 4.2 | D7: 5.01
A9: Coverage gates — below these a score is suppressed rather than computed
A10: Rule | B10: Threshold | C10: Meaning
A11: pillar_min | B11: 0.6 | C11: A pillar reads Not rated unless this share of its indicators carry a level.
A12: cms_min | B12: 0.7 | C12: Capability coverage required before any overall stage is issued.
A13: ems_min | B13: 0.6 | C13: Ecosystem coverage required before EMS is reported.
A14: evidence_adequacy_min | B14: 0.5 | C14: Minimum weighted evidence adequacy for a read-out to stand.
A16: Stage floors — the non-compensatory cascade. A stage is reached only when every floor is met.
A17: Rule | B17: Floor | C17: Meaning
A18: stage2_cms | B18: 2.6 | C18: CMS floor required to be at Stage 2.
A19: stage3_cms | B19: 3.4 | C19: CMS floor required to be at Stage 3.
A20: stage3_ems | B20: 2.6 | C20: EMS floor required to be at Stage 3.
A21: stage4_cms | B21: 4.2 | C21: CMS floor required to be at Stage 4.
A22: stage4_ems | B22: 3.4 | C22: EMS floor required to be at Stage 4.
A23: stage4_oes | B23: 2.6 | C23: OES floor required to be at Stage 4.
A24: stage5_cms | B24: 4.5 | C24: CMS floor required to be at Stage 5.
A25: stage5_ems | B25: 4.2 | C25: EMS floor required to be at Stage 5.
A26: stage5_oes | B26: 3.4 | C26: OES floor required to be at Stage 5.
A28: Leapfrog fragility
A29: Rule | B29: Threshold | C29: Meaning
A30: leapfrog_gap | B30: 1.5 | C30: Foundation minus transformation gap above which the assessment is flagged as leapfrog-fragile: advanced applications resting on weak foundations.
A32: Confidence weights — applied when evidence adequacy is computed
A33: Confidence | B33: Weight | C33: Meaning
A34: High | B34: 1 | C34: Per-reading tag set when the reading is recorded.
A35: Medium | B35: 0.6 | C35: Per-reading tag set when the reading is recorded.
A36: Low | B36: 0.3 | C36: Per-reading tag set when the reading is recorded.
A37: Data Gap | B37: 0 | C37: A Data Gap is recorded and weighted zero, rather than left blank.

Sheet Process ladder
A1: Step | B1: Name | C1: Executor | D1: Output | E1: What happens
A2: 1 | B2: Populate indicators | C2: Machine (+ assessor for qualitative) | D2: Populated workbook: 102 indicators with value, source name, source URL, year | E2: Populate all 102 indicators. Quantitative indicators score themselves via the numeric-threshold rule on the Indicators sheet. Qualitative indicators are scored 1–5 by the assessor against the Qualitative Anchors sheet; the machine may propose a level, but the assessor level always wins. Every reading records source name, source URL, and observation year.
A3: 2 | B3: Score evidence quality | C3: Machine (automated) | D3: Evidence Quality Index per pillar; refresh list; verify list | E3: For each reading, tag confidence High / Medium / Low / Data Gap. Staleness is automatic (year vs indicator max age). Coverage per pillar is automatic. Weighted evidence adequacy per read-out is automatic. All five feed a single Evidence Quality Index (green / amber / red) per pillar, plus two underlying lists: Refresh (stale readings + Low-confidence readings) and Verify (data gaps + unmeasured core gates).
A4: 3 | B4: Compile diagnostic package | C4: Machine (automated) | D4: Diagnostic Package (PDF) handed to TTL | E4: Render the Diagnostic Package sheet: three read-outs (CMS/EMS/OES), provisional stage with caveat, core-gate audit (14 prerequisites), top binding constraints by pillar, Refresh list, Verify list, and the full 102-indicator appendix with source, year, confidence. Export as PDF. This is the single artefact handed to the TTL.
A5: 4 | B5: Draft the DAR offline | C5: TTL + team, post-mandate | D5: The DAR | E5: The TTL and team draft the DAR offline, after the government mandate, drawing on the Diagnostic Package as evidence. This workbook is an input to that process, not part of it. The DAR is authored, validated with the steering committee, adopted and disclosed under the DAR methodology, which is separate from this workbook.
B7: Where the mandate sits | E7: The government mandate does not gate the workbook. Steps 1–3 can run on public evidence at any time and produce a diagnostic package for internal Bank use. The mandate gates the DAR: nothing is called a DAR before the government has mandated the work. The Diagnostic Package is watermarked accordingly.

Sheet Glossary
A1: Term | B1: Name | C1: Definition
A2: CMS | B2: Capability Maturity Score | C2: Weighted mean of C1–C4 pillar levels (25/30/25/20). Reported 1–5.
A3: EMS | B3: Ecosystem Maturity Score | C3: Weighted mean of E1 (70%) and E2 (30%) pillars.
A4: OES | B4: Outcome & Equity Score | C4: O1 pillar mean level. Deliberately kept separate from CMS/EMS.
A5: Stage | B5: Overall stage | C5: Stage 1 (Foundation constrained) through Stage 5 (Transformative). Derived non-compensatively from CMS/EMS/OES subject to core-gate and coverage rules.
A6: Core gate | B6: Core-gate indicator | C6: 14 foundational indicators treated as prerequisites, not points. L1 caps the stage at 1; unmeasured suppresses the stage entirely.
A7: Coverage | B7: Coverage gate | C7: Share of a pillar's indicators that carry an assigned level. Below 60% the pillar reads Not rated; a composite containing an unrated pillar is also suppressed.
A8: Confidence | B8: Confidence weight | C8: High=1.0, Medium=0.6, Low=0.3. Used to compute Weighted Evidence Adequacy.
A9: Adequacy | B9: Weighted evidence adequacy | C9: Confidence-weighted share of scored indicators. Must clear 0.5 for the read-out to stand.
A10: Stale | B10: Stale evidence | C10: A reading whose observation year is older than the indicator's max age (2 or 3 years).
A11: Data Gap | B11: Data Gap | C11: No assessor level and no machine level. Excluded from scoring, reported separately.
A12: Provisional | B12: Provisional level | C12: A level derived by machine from a threshold rule, not yet confirmed by an assessor.
A13: Engagement package | B13: Engagement package | C13: Everything assembled before the government mandate. No stage is claimable however complete the evidence looks.
