Workbook

Sheet Read me
A1: DAMM 1.3-DRAFT — model configuration
A3: Model | B3: DAMM
A4: Version | B4: 1.3-DRAFT
A5: Status | B5: BETA / PILOT - scoring core; DESIGN DRAFT - operationalization layer
A6: Assessment year | B6: 2026
A7: Extracted from | B7: DAMM_v1.3_Workbook_DRAFT.xlsx
A8: Indicators | B8: =COUNTA(Indicators!A2:A200) -> 97
A9: Pillars | B9: =COUNTIF(Pillars!$C$2:$C$50,"Context")+COUNTIF(Pillars!$C$2:$C$50,"Capability")+COUNTIF(Pillars!$C$2:$C$50,"Ecosystem")+COUNTIF(Pillars!$C$2:$C$50,"Outcome") -> 8
A10: Core gates | B10: =COUNTA('Core gates'!A2:A50) -> 13
A11: Ladder steps | B11: =COUNTA('Decision ladder'!A2:A50) -> 8
A13: Prohibitions wired into the model
A14: 1 | B14: No cross-country ranking
A15: 2 | B15: No maturity stage before human validation (engagement-package rule)
A16: 3 | B16: No DAMM score or stage movement as PDO indicator, DLI or disbursement condition
A17: 4 | B17: No automatic financing, procurement, vendor or technology decisions
A19: Sheets
A20: Indicators | B20: All 97 indicators: pillar, role, method, direction, core-gate flag, staleness limit and the value thresholds for levels 2-5.
A21: Level anchors | B21: The written L1-L5 anchor text for every indicator — what each level means in words.
A22: Pillars | B22: The 8 pillars with their role and weight. C0 is context and is never aggregated into a score.
A23: Core gates | B23: The 13 prerequisite indicators. One at Level 1 caps the stage; one unmeasured suppresses it.
A24: Scoring rules | B24: Bands, stage thresholds, coverage gates and confidence weights.
A25: Decision ladder | B25: The 8 steps from automated diagnostic to adoption, and who decides each.
A26: Glossary | B26: CMS, EMS, OES and the other terms, defined as the model defines them.
A27: Methodology | B27: Purpose, explicit non-purposes, scoring rules, the cascade and provenance requirements.
A28: Model outline | B28: The outline carried inside the model file. NOTE: the DAR Studio application drafts to its own 17-chapter + 11-annex outline instead, per the master prompt.
A30: Reading the thresholds
B31: Quantitative indicators carry four thresholds. Where Direction is Higher, a value at or above the L5 threshold scores 5, at or above L4 scores 4, and so on; below the L2 threshold scores 1.
B32: Where Direction is Lower, the comparison reverses: at or below the L5 threshold scores 5.
B33: Where Direction is N/A there are no thresholds — the indicator is an anchored rubric assessed against the words in 'Level anchors', or a context profile that is never scored.
B34: Source of every value in this workbook: src/data/model_v1_3.json in the DAR Studio repository, itself extracted from DAMM_v1.3_Workbook_DRAFT.xlsx.

Sheet Indicators
A1: ID | B1: Indicator | C1: Pillar | D1: Pillar name | E1: Role | F1: Source type | G1: Method | H1: Direction | I1: Core gate | J1: Max age (yrs) | K1: L2 threshold | L1: L3 threshold | M1: L4 threshold | N1: L5 threshold | O1: Rubric status | P1: Calibration note
A2: 1.1 | B2: Agriculture value added per worker (constant 2015 USD) | C2: C0 | D2: C0: Agricultural context & need | E2: Context | F2: Global | G2: Context profile (not aggregated) | H2: N/A | J2: 3 | O2: Context only | P2: Report level, distribution and trend separately; exclude from maturity arithmetic.
A3: 1.2 | B3: Cereal yield (kg per hectare) | C3: C0 | D3: C0: Agricultural context & need | E3: Context | F3: Global | G3: Context profile (not aggregated) | H3: N/A | J3: 3 | O3: Context only | P3: Report level, distribution and trend separately; exclude from maturity arithmetic.
A4: 1.3 | B4: Employment in agriculture (% of total employment) | C4: C0 | D4: C0: Agricultural context & need | E4: Context | F4: Global | G4: Context profile (not aggregated) | H4: N/A | J4: 3 | O4: Context only | P4: Report level, distribution and trend separately; exclude from maturity arithmetic.
A5: 1.4 | B5: Food production index (2014-2016 = 100) | C5: C0 | D5: C0: Agricultural context & need | E5: Context | F5: Global | G5: Context profile (not aggregated) | H5: N/A | J5: 3 | O5: Context only | P5: Report level, distribution and trend separately; exclude from maturity arithmetic.
A6: 1.5 | B6: Post-harvest loss rate (%) | C6: C0 | D6: C0: Agricultural context & need | E6: Context | F6: Local | G6: Context profile (not aggregated) | H6: N/A | J6: 2 | O6: Context only | P6: Report level, distribution and trend separately; exclude from maturity arithmetic.
A7: 1.6 | B7: Smallholder access to formal markets (%) | C7: C0 | D7: C0: Agricultural context & need | E7: Context | F7: Local | G7: Context profile (not aggregated) | H7: N/A | J7: 2 | O7: Context only | P7: Report level, distribution and trend separately; exclude from maturity arithmetic.
A8: 1.7 | B8: Agricultural credit access (% of farmers) | C8: C0 | D8: C0: Agricultural context & need | E8: Context | F8: Local | G8: Context profile (not aggregated) | H8: N/A | J8: 2 | O8: Context only | P8: Report level, distribution and trend separately; exclude from maturity arithmetic.
A9: 1.8 | B9: Farmers using climate-smart/sustainable practices (%) | C9: C0 | D9: C0: Agricultural context & need | E9: Context | F9: Local | G9: Context profile (not aggregated) | H9: N/A | J9: 2 | O9: Context only | P9: Report level, distribution and trend separately; exclude from maturity arithmetic.
A10: 1.9 | B10: National innovation/extension programs with digital component | C10: C4 | D10: C4: Human & institutional capacity | E10: Capability | F10: Local | G10: Anchored capability rubric | H10: N/A | J10: 2 | O10: Anchored rubric - validate through panel scoring | P10: Score through a multi-stakeholder evidence panel; require documentary evidence and record dissent.
A11: 2.1 | B11: Rural population covered by at least 3G (%) | C11: C1 | D11: C1: Connectivity & affordable access | E11: Capability | F11: Global | G11: Quantitative threshold | H11: Higher | I11: YES | J11: 3 | K11: 20 | L11: 40 | M11: 60 | N11: 80 | O11: PROVISIONAL - calibrate against peer distribution | P11: Use the suggested level as a starting point only; document any override and recalibrate cut-offs using peer distributions.
A12: 2.2 | B12: Rural population covered by at least 4G (%) | C12: C1 | D12: C1: Connectivity & affordable access | E12: Capability | F12: Global | G12: Quantitative threshold | H12: Higher | J12: 3 | K12: 20 | L12: 40 | M12: 60 | N12: 80 | O12: PROVISIONAL - calibrate against peer distribution | P12: Use the suggested level as a starting point only; document any override and recalibrate cut-offs using peer distributions.
A13: 2.3 | B13: Active mobile broadband subscriptions per 100 inhabitants | C13: C1 | D13: C1: Connectivity & affordable access | E13: Capability | F13: Global | G13: Quantitative threshold | H13: Higher | J13: 3 | K13: 20 | L13: 40 | M13: 70 | N13: 100 | O13: PROVISIONAL - calibrate against peer distribution | P13: Use the suggested level as a starting point only; document any override and recalibrate cut-offs using peer distributions.
A14: 2.4 | B14: Individuals using the Internet (% of population) | C14: C1 | D14: C1: Connectivity & affordable access | E14: Capability | F14: Global | G14: Quantitative threshold | H14: Higher | J14: 3 | K14: 20 | L14: 40 | M14: 60 | N14: 80 | O14: PROVISIONAL - calibrate against peer distribution | P14: Use the suggested level as a starting point only; document any override and recalibrate cut-offs using peer distributions.
A15: 2.5 | B15: Mobile broadband basket price (% GNI per capita) | C15: C1 | D15: C1: Connectivity & affordable access | E15: Capability | F15: Global | G15: Quantitative threshold | H15: Lower | I15: YES | J15: 3 | K15: 10 | L15: 5 | M15: 2 | N15: 1 | O15: PROVISIONAL - calibrate against peer distribution | P15: Use the suggested level as a starting point only; document any override and recalibrate cut-offs using peer distributions.
A16: 2.6 | B16: Adults with mobile phone (% age 15+) | C16: C1 | D16: C1: Connectivity & affordable access | E16: Capability | F16: Global | G16: Quantitative threshold | H16: Higher | J16: 3 | K16: 20 | L16: 40 | M16: 60 | N16: 80 | O16: PROVISIONAL - calibrate against peer distribution | P16: Use the suggested level as a starting point only; document any override and recalibrate cut-offs using peer distributions.
A17: 2.7 | B17: Smartphone ownership among rural/agricultural population (%) | C17: C1 | D17: C1: Connectivity & affordable access | E17: Capability | F17: Local | G17: Quantitative threshold | H17: Higher | J17: 2 | K17: 20 | L17: 40 | M17: 60 | N17: 80 | O17: PROVISIONAL - calibrate against peer distribution | P17: Use the suggested level as a starting point only; document any override and recalibrate cut-offs using peer distributions.
A18: 2.8 | B18: Average mobile data cost in rural areas (USD per GB) | C18: C1 | D18: C1: Connectivity & affordable access | E18: Capability | F18: Local | G18: Quantitative threshold | H18: Lower | J18: 2 | K18: 10 | L18: 5 | M18: 2 | N18: 1 | O18: PROVISIONAL - calibrate against peer distribution | P18: Use the suggested level as a starting point only; document any override and recalibrate cut-offs using peer distributions.
A19: 2.9 | B19: Electricity access in rural areas (%) | C19: C1 | D19: C1: Connectivity & affordable access | E19: Capability | F19: Local | G19: Quantitative threshold | H19: Higher | I19: YES | J19: 2 | K19: 20 | L19: 40 | M19: 60 | N19: 80 | O19: PROVISIONAL - calibrate against peer distribution | P19: Use the suggested level as a starting point only; document any override and recalibrate cut-offs using peer distributions.
A20: 2.10 | B20: Average download speed in agricultural areas (Mbps) | C20: C1 | D20: C1: Connectivity & affordable access | E20: Capability | F20: Local | G20: Quantitative threshold | H20: Higher | J20: 2 | K20: 2 | L20: 5 | M20: 10 | N20: 25 | O20: PROVISIONAL - calibrate against peer distribution | P20: Use the suggested level as a starting point only; document any override and recalibrate cut-offs using peer distributions.
A21: 2.11 | B21: Device financing/subsidy schemes for farmers | C21: C1 | D21: C1: Connectivity & affordable access | E21: Capability | F21: Local | G21: Anchored capability rubric | H21: N/A | J21: 2 | O21: Anchored rubric - validate through panel scoring | P21: Score through a multi-stakeholder evidence panel; require documentary evidence and record dissent.
A22: 3.1 | B22: UN E-Government Development Index (EGDI) | C22: C2 | D22: C2: Data infrastructure & DPI | E22: Capability | F22: Global | G22: Quantitative threshold | H22: Higher | J22: 3 | K22: 0.2 | L22: 0.4 | M22: 0.6 | N22: 0.8 | O22: PROVISIONAL - calibrate against peer distribution | P22: Use the suggested level as a starting point only; document any override and recalibrate cut-offs using peer distributions.
A23: 3.2 | B23: Open Data Inventory (ODIN) score | C23: C2 | D23: C2: Data infrastructure & DPI | E23: Capability | F23: Global | G23: Quantitative threshold | H23: Higher | J23: 3 | K23: 20 | L23: 40 | M23: 60 | N23: 80 | O23: PROVISIONAL - calibrate against peer distribution | P23: Use the suggested level as a starting point only; document any override and recalibrate cut-offs using peer distributions.
A24: 3.3 | B24: National farmer registry/database | C24: C2 | D24: C2: Data infrastructure & DPI | E24: Capability | F24: Local | G24: Anchored capability rubric | H24: N/A | I24: YES | J24: 2 | O24: Anchored rubric - validate through panel scoring | P24: Score through a multi-stakeholder evidence panel; require documentary evidence and record dissent.
A25: 3.4 | B25: Digital land/plot registration system | C25: C2 | D25: C2: Data infrastructure & DPI | E25: Capability | F25: Local | G25: Anchored capability rubric | H25: N/A | J25: 2 | O25: Anchored rubric - validate through panel scoring | P25: Score through a multi-stakeholder evidence panel; require documentary evidence and record dissent.
A26: 3.5 | B26: National agricultural data portal / open data | C26: C2 | D26: C2: Data infrastructure & DPI | E26: Capability | F26: Local | G26: Anchored capability rubric | H26: N/A | J26: 2 | O26: Anchored rubric - validate through panel scoring | P26: Score through a multi-stakeholder evidence panel; require documentary evidence and record dissent.
A27: 3.6 | B27: Weather/climate data infrastructure for agriculture | C27: C2 | D27: C2: Data infrastructure & DPI | E27: Capability | F27: Local | G27: Anchored capability rubric | H27: N/A | J27: 2 | O27: Anchored rubric - validate through panel scoring | P27: v1.3 rewrite: anchor now tests the full climate-services chain (observation -> forecast -> last-mile reach), not data infrastructure alone.
A28: 3.7 | B28: Satellite/earth observation data integration capability | C28: C2 | D28: C2: Data infrastructure & DPI | E28: Capability | F28: Local | G28: Anchored capability rubric | H28: N/A | J28: 2 | O28: Anchored rubric - validate through panel scoring | P28: Score through a multi-stakeholder evidence panel; require documentary evidence and record dissent.
A29: 3.8 | B29: National soil map/database (digital) | C29: C2 | D29: C2: Data infrastructure & DPI | E29: Capability | F29: Local | G29: Anchored capability rubric | H29: N/A | J29: 2 | O29: Anchored rubric - validate through panel scoring | P29: Score through a multi-stakeholder evidence panel; require documentary evidence and record dissent.
A30: 3.9 | B30: Digital advisory platforms reaching >10,000 users | C30: C2 | D30: C2: Data infrastructure & DPI | E30: Capability | F30: Local | G30: Quantitative threshold | H30: Higher | J30: 2 | K30: 20 | L30: 40 | M30: 60 | N30: 80 | O30: PROVISIONAL - calibrate against peer distribution | P30: Use the suggested level as a starting point only; document any override and recalibrate cut-offs using peer distributions.
A31: 3.10 | B31: Digital agricultural market/e-commerce platforms (>5,000 active users) | C31: C2 | D31: C2: Data infrastructure & DPI | E31: Capability | F31: Local | G31: Anchored capability rubric | H31: N/A | J31: 2 | O31: Anchored rubric - validate through panel scoring | P31: Score through a multi-stakeholder evidence panel; require documentary evidence and record dissent.
A32: 3.11 | B32: Interoperability standards for agricultural data | C32: C2 | D32: C2: Data infrastructure & DPI | E32: Capability | F32: Local | G32: Anchored capability rubric | H32: N/A | I32: YES | J32: 2 | O32: Anchored rubric - validate through panel scoring | P32: Score through a multi-stakeholder evidence panel; require documentary evidence and record dissent.
A33: 3.12 | B33: AI-ready agricultural datasets | C33: C2 | D33: C2: Data infrastructure & DPI | E33: Capability | F33: Local | G33: Anchored capability rubric | H33: N/A | J33: 2 | O33: Anchored rubric - validate through panel scoring | P33: Score through a multi-stakeholder evidence panel; require documentary evidence and record dissent.
A34: 4.1 | B34: Data protection/privacy law | C34: C3 | D34: C3: Policy, governance & safeguards | E34: Capability | F34: Global | G34: Anchored capability rubric | H34: N/A | I34: YES | J34: 3 | O34: Anchored rubric - validate through panel scoring | P34: Score through a multi-stakeholder evidence panel; require documentary evidence and record dissent.
A35: 4.2 | B35: Cybersecurity legal framework (ITU GCI) | C35: C3 | D35: C3: Policy, governance & safeguards | E35: Capability | F35: Global | G35: Quantitative threshold | H35: Higher | I35: YES | J35: 3 | K35: 0.2 | L35: 0.4 | M35: 0.6 | N35: 0.8 | O35: PROVISIONAL - calibrate against peer distribution | P35: Use the suggested level as a starting point only; document any override and recalibrate cut-offs using peer distributions.
A36: 4.3 | B36: Government AI Readiness Index | C36: C3 | D36: C3: Policy, governance & safeguards | E36: Capability | F36: Global | G36: Quantitative threshold | H36: Higher | J36: 3 | K36: 20 | L36: 40 | M36: 60 | N36: 80 | O36: PROVISIONAL - calibrate against peer distribution | P36: Use the suggested level as a starting point only; document any override and recalibrate cut-offs using peer distributions.
A37: 4.4 | B37: National digital agriculture strategy | C37: C3 | D37: C3: Policy, governance & safeguards | E37: Capability | F37: Local | G37: Anchored capability rubric | H37: N/A | J37: 2 | O37: Anchored rubric - validate through panel scoring | P37: Score through a multi-stakeholder evidence panel; require documentary evidence and record dissent.
A38: 4.5 | B38: Agricultural data governance framework | C38: C3 | D38: C3: Policy, governance & safeguards | E38: Capability | F38: Local | G38: Anchored capability rubric | H38: N/A | I38: YES | J38: 2 | O38: Anchored rubric - validate through panel scoring | P38: Score through a multi-stakeholder evidence panel; require documentary evidence and record dissent.
A39: 4.6 | B39: National AI strategy with agriculture component | C39: C3 | D39: C3: Policy, governance & safeguards | E39: Capability | F39: Local | G39: Anchored capability rubric | H39: N/A | J39: 2 | O39: Anchored rubric - validate through panel scoring | P39: Score through a multi-stakeholder evidence panel; require documentary evidence and record dissent.
A40: 4.7 | B40: Digital ID system coverage (% of population) | C40: C3 | D40: C3: Policy, governance & safeguards | E40: Capability | F40: Local | G40: Quantitative threshold | H40: Higher | J40: 2 | K40: 20 | L40: 40 | M40: 60 | N40: 80 | O40: PROVISIONAL - calibrate against peer distribution | P40: Use the suggested level as a starting point only; document any override and recalibrate cut-offs using peer distributions.
...

Sheet Level anchors
A1: ID | B1: Indicator | C1: Level 1 | D1: Level 2 | E1: Level 3 | F1: Level 4 | G1: Level 5
A2: 1.1 | B2: Agriculture value added per worker (constant 2015 USD) | C2: Profile the observed level and trend; do not interpret as digital maturity. | D2: Profile only. | E2: Profile only. | F2: Profile only. | G2: Profile only.
A3: 1.2 | B3: Cereal yield (kg per hectare) | C3: Profile the observed level and trend; do not interpret as digital maturity. | D3: Profile only. | E3: Profile only. | F3: Profile only. | G3: Profile only.
A4: 1.3 | B4: Employment in agriculture (% of total employment) | C4: Profile the observed level and trend; do not interpret as digital maturity. | D4: Profile only. | E4: Profile only. | F4: Profile only. | G4: Profile only.
A5: 1.4 | B5: Food production index (2014-2016 = 100) | C5: Profile the observed level and trend; do not interpret as digital maturity. | D5: Profile only. | E5: Profile only. | F5: Profile only. | G5: Profile only.
A6: 1.5 | B6: Post-harvest loss rate (%) | C6: Profile the observed level and trend; do not interpret as digital maturity. | D6: Profile only. | E6: Profile only. | F6: Profile only. | G6: Profile only.
A7: 1.6 | B7: Smallholder access to formal markets (%) | C7: Profile the observed level and trend; do not interpret as digital maturity. | D7: Profile only. | E7: Profile only. | F7: Profile only. | G7: Profile only.
A8: 1.7 | B8: Agricultural credit access (% of farmers) | C8: Profile the observed level and trend; do not interpret as digital maturity. | D8: Profile only. | E8: Profile only. | F8: Profile only. | G8: Profile only.
A9: 1.8 | B9: Farmers using climate-smart/sustainable practices (%) | C9: Profile the observed level and trend; do not interpret as digital maturity. | D9: Profile only. | E9: Profile only. | F9: Profile only. | G9: Profile only.
A10: 1.9 | B10: National innovation/extension programs with digital component | C10: No credible national innovation/extension programs with digital component capability, or isolated informal activity only. | D10: Pilot or ad hoc national innovation/extension programs with digital component; narrow coverage, unclear ownership or donor dependence. | E10: Operational national innovation/extension programs with digital component with defined ownership and partial coverage; adoption or interoperability gaps remain. | F10: Scaled and funded national innovation/extension programs with digital component, with accountable governance, interoperability and broad use. | G10: Institutionalized, inclusive and resilient national innovation/extension programs with digital component, continuously improved and supported by verified outcomes.
A11: 2.1 | B11: Rural population covered by at least 3G (%) | C11: < 20 | D11: 20 to < 40 | E11: 40 to < 60 | F11: 60 to < 80 | G11: >= 80
A12: 2.2 | B12: Rural population covered by at least 4G (%) | C12: < 20 | D12: 20 to < 40 | E12: 40 to < 60 | F12: 60 to < 80 | G12: >= 80
... A98: 8.15 | B98: Environmental sustainability of digital agriculture systems | C98: < 20 | D98: 20 to < 40 | E98: 40 to < 60 | F98: 60 to < 80 | G98: >= 80

Sheet Pillars
A1: Pillar | B1: Name | C1: Role | D1: Weight | E1: Aggregated | F1: Indicators | G1: Core gates
A2: C0 | B2: Agricultural context & need | C2: Context | E2: No — context only | F2: =COUNTIF(Indicators!$C$2:$C$98,$A2) -> 8 | G2: =COUNTIFS(Indicators!$C$2:$C$98,$A2,Indicators!$I$2:$I$98,"YES") -> 0
A3: C1 | B3: Connectivity & affordable access | C3: Capability | D3: 0.25 | E3: Yes | F3: =COUNTIF(Indicators!$C$2:$C$98,$A3) -> 11 | G3: =COUNTIFS(Indicators!$C$2:$C$98,$A3,Indicators!$I$2:$I$98,"YES") -> 3
A4: C2 | B4: Data infrastructure & DPI | C4: Capability | D4: 0.3 | E4: Yes | F4: =COUNTIF(Indicators!$C$2:$C$98,$A4) -> 12 | G4: =COUNTIFS(Indicators!$C$2:$C$98,$A4,Indicators!$I$2:$I$98,"YES") -> 2
A5: C3 | B5: Policy, governance & safeguards | C5: Capability | D5: 0.25 | E5: Yes | F5: =COUNTIF(Indicators!$C$2:$C$98,$A5) -> 13 | G5: =COUNTIFS(Indicators!$C$2:$C$98,$A5,Indicators!$I$2:$I$98,"YES") -> 4
A6: C4 | B6: Human & institutional capacity | C6: Capability | D6: 0.2 | E6: Yes | F6: =COUNTIF(Indicators!$C$2:$C$98,$A6) -> 13 | G6: =COUNTIFS(Indicators!$C$2:$C$98,$A6,Indicators!$I$2:$I$98,"YES") -> 2
A7: E1 | B7: Innovation & private sector | C7: Ecosystem | D7: 0.55 | E7: Yes | F7: =COUNTIF(Indicators!$C$2:$C$98,$A7) -> 13 | G7: =COUNTIFS(Indicators!$C$2:$C$98,$A7,Indicators!$I$2:$I$98,"YES") -> 0
A8: E2 | B8: Responsible AI & emerging tech | C8: Ecosystem | D8: 0.45 | E8: Yes | F8: =COUNTIF(Indicators!$C$2:$C$98,$A8) -> 12 | G8: =COUNTIFS(Indicators!$C$2:$C$98,$A8,Indicators!$I$2:$I$98,"YES") -> 2
A9: O1 | B9: Inclusion, sustainability & outcomes | C9: Outcome | D9: 1 | E9: Yes | F9: =COUNTIF(Indicators!$C$2:$C$98,$A9) -> 15 | G9: =COUNTIFS(Indicators!$C$2:$C$98,$A9,Indicators!$I$2:$I$98,"YES") -> 0
A10: Total | F10: =SUM(F2:F9) -> 97 | G10: =SUM(G2:G9) -> 13
A12: Weights sum to 1.00 within each role family
A13: Capability (C1-C4) | D13: =SUMIF($C$2:$C$9,"Capability",$D$2:$D$9) -> 1
A14: Ecosystem (E1-E2) | D14: =SUMIF($C$2:$C$9,"Ecosystem",$D$2:$D$9) -> 1
A15: Outcome (O1) | D15: =SUMIF($C$2:$C$9,"Outcome",$D$2:$D$9) -> 1
A16: C0 carries no weight: it is context and is never aggregated.

Sheet Core gates
A1: ID | B1: Indicator | C1: Pillar | D1: Method | E1: Why it gates
A2: 2.1 | B2: Rural population covered by at least 3G (%) | C2: C1 | D2: Quantitative threshold | E2: Prerequisite: at Level 1 it caps the overall stage at Stage 1; unmeasured, it suppresses the stage entirely.
A3: 2.5 | B3: Mobile broadband basket price (% GNI per capita) | C3: C1 | D3: Quantitative threshold | E3: Prerequisite: at Level 1 it caps the overall stage at Stage 1; unmeasured, it suppresses the stage entirely.
A4: 2.9 | B4: Electricity access in rural areas (%) | C4: C1 | D4: Quantitative threshold | E4: Prerequisite: at Level 1 it caps the overall stage at Stage 1; unmeasured, it suppresses the stage entirely.
A5: 3.3 | B5: National farmer registry/database | C5: C2 | D5: Anchored capability rubric | E5: Prerequisite: at Level 1 it caps the overall stage at Stage 1; unmeasured, it suppresses the stage entirely.
A6: 3.11 | B6: Interoperability standards for agricultural data | C6: C2 | D6: Anchored capability rubric | E6: Prerequisite: at Level 1 it caps the overall stage at Stage 1; unmeasured, it suppresses the stage entirely.
A7: 4.1 | B7: Data protection/privacy law | C7: C3 | D7: Anchored capability rubric | E7: Prerequisite: at Level 1 it caps the overall stage at Stage 1; unmeasured, it suppresses the stage entirely.
A8: 4.2 | B8: Cybersecurity legal framework (ITU GCI) | C8: C3 | D8: Quantitative threshold | E8: Prerequisite: at Level 1 it caps the overall stage at Stage 1; unmeasured, it suppresses the stage entirely.
A9: 4.5 | B9: Agricultural data governance framework | C9: C3 | D9: Anchored capability rubric | E9: Prerequisite: at Level 1 it caps the overall stage at Stage 1; unmeasured, it suppresses the stage entirely.
A10: 4.9 | B10: Inter-ministerial coordination mechanism for digital agriculture | C10: C3 | D10: Anchored capability rubric | E10: Prerequisite: at Level 1 it caps the overall stage at Stage 1; unmeasured, it suppresses the stage entirely.
A11: 5.5 | B11: Extension workers trained in digital tools (%) | C11: C4 | D11: Quantitative threshold | E11: Prerequisite: at Level 1 it caps the overall stage at Stage 1; unmeasured, it suppresses the stage entirely.
A12: 5.7 | B12: Dedicated digital/AI units in Ministry of Agriculture | C12: C4 | D12: Anchored capability rubric | E12: Prerequisite: at Level 1 it caps the overall stage at Stage 1; unmeasured, it suppresses the stage entirely.
... A14: 7.12 | B14: Farmer consent and data rights in AI systems | C14: E2 | D14: Anchored capability rubric | E14: Prerequisite: at Level 1 it caps the overall stage at Stage 1; unmeasured, it suppresses the stage entirely.

Sheet Scoring rules
A1: Score bands (applied to every pillar score and to CMS, EMS and OES)
A2: Level | B2: Band | C2: From | D2: To
A3: 1 | B3: Nascent | C3: 1 | D3: 1.8
A4: 2 | B4: Emerging | C4: 1.8 | D4: 2.6
A5: 3 | B5: Established | C5: 2.6 | D5: 3.4
A6: 4 | B6: Advanced | C6: 3.4 | D6: 4.2
A7: 5 | B7: Transformative | C7: 4.2 | D7: 5.01
A9: Coverage gates — below these, a score is suppressed rather than computed
A10: Rule | B10: Threshold | C10: Meaning
A11: pillar_min | B11: 0.6 | C11: A pillar reports Not rated unless this share of its indicators carry a level.
A12: cms_min | B12: 0.7 | C12: Overall capability coverage required before any stage may be issued.
A13: ems_min | B13: 0.6 | C13: Ecosystem coverage required before EMS is reported.
A14: evidence_adequacy_min | B14: 0.5 | C14: Minimum evidence adequacy for the read-out to stand.
A16: Stage thresholds — the non-compensatory cascade
A17: Rule | B17: Threshold | C17: Meaning
A18: stage2_cms | B18: 2.6 | C18: Required to reach Stage 2 on CMS.
A19: stage3_cms | B19: 3.4 | C19: Required to reach Stage 3 on CMS.
A20: stage3_ems | B20: 2.6 | C20: Required to reach Stage 3 on EMS.
A21: stage4_cms | B21: 4.2 | C21: Required to reach Stage 4 on CMS.
A22: stage4_ems | B22: 3.4 | C22: Required to reach Stage 4 on EMS.
A23: stage4_oes | B23: 2.6 | C23: Required to reach Stage 4 on OES.
A25: Confidence weights
A26: Confidence | B26: Weight | C26: Meaning
A27: High | B27: 1 | C27: Applied to the evidence behind a reading when adequacy is computed.
A28: Medium | B28: 0.6 | C28: Applied to the evidence behind a reading when adequacy is computed.
A29: Low/Estimated | B29: 0.3 | C29: Applied to the evidence behind a reading when adequacy is computed.

Sheet Decision ladder
A1: Step | B1: Rung | C1: Name | D1: Decider | E1: Decision recorded | F1: Guidance
A2: 1 | B2: T0 | C2: Automated diagnostic | D2: machine | F2: The machine collects public evidence and routes named gaps to data stewards. Nothing here claims a maturity stage - it is an engagement package assembled for your Step 2 decision.
A3: 2 | B3: D1 | C3: Engage / mode / budget | D3: TTL | E3: Engage or defer; assessment mode; budget and team | F3: Decide whether to engage, in what assessment mode, and with what budget and team. The machine drafts the memo and frames the options; the decision - including the rejected alternatives - is yours and is recorded.
A4: 3 | B4: D2 | C4: Targeting hypotheses | D4: TTL | E4: Chain shortlist and segmentation to propose to government | F4: Shortlist the value chains and segmentation to propose to government. Use the M1 targeting module in the exported workbook for the analysis; record the shortlist (and the chains you rejected) as the Step 3 decision.
A5: 4 | B5: D3 | C5: Evidence plan & mission design | D5: TTL / management | E5: Evidence plan and mission design | F5: Plan how every unmeasured core gate and stale item will be evidenced, and design the mission. Each named gap already carries an authoritative steward route from Step 1.
A6: 5 | B6: G | C6: Government gates | D6: Government | E6: Mandate letter; steering committee; endorsed chain selection | F6: Government decides: mandate letter, steering committee, endorsed chain selection. Nothing before this step carries a stage - the engagement-package rule holds until the mandate exists.
A7: 6 | B7: D4 | C7: Validated read-outs | D7: Evidence panel / steering committee | E7: Validated read-outs to the workshop | F7: The evidence panel validates the read-outs. Setting an assessor level converts machine imports to human-validated evidence; every core gate must be measured before a stage can be read out to the workshop.
A8: 7 | B8: D5 | C8: Portfolio scenario | D8: Steering committee (finance sign-off) | E8: Portfolio scenario and envelope | F8: Assemble the portfolio scenario and envelope with finance sign-off, using the workbook's investment appraisal (unit costs, inclusion and DPI gates).
A9: 8 | B9: D6 | C9: Adopt & disclose | D9: Decision authority / government | E9: Adopt, disclose and version | F9: Adopt the DAR, disclose it, and version the record. Export and archive the final workbook as the auditable artefact.

Sheet Glossary
A1: Term | B1: Name | C1: Short | D1: Definition
A2: CMS | B2: Capability Maturity Score | C2: Capability | D2: Government capability, on the 1-5 level scale. Each of the four capability pillars (connectivity; data and DPI; policy and governance; human capacity) is the plain mean of the levels assigned within it, and CMS combines those four pillar scores using the pillar weights. It is reported only when every one of the four pillars has at least 60% of its indicators levelled; if any pillar falls short, CMS reads Not rated rather than being computed from a partial picture.
A3: EMS | B3: Ecosystem Maturity Score | C3: Ecosystem | D3: The same calculation over the two ecosystem pillars (innovation and private sector; responsible AI and emerging tech), describing the market and innovation environment around government capability. It too is suppressed unless both of its pillars clear 60% coverage.
A4: OES | B4: Outcome & Equity Score | C4: Outcomes | D4: The read-out for the single outcomes pillar - inclusion, sustainability and realised results - so it is that pillar's own mean level, not a weighted blend. It is deliberately kept separate from capability: a country can build systems without yet moving outcomes, and the model refuses to average that away.
A5: Stage | B5: Maturity stage | C5: Overall stage | D5: The single overall read-out, running from Stage 1 (Foundation constrained) through Stage 2 (Capability building), Stage 3 (Ecosystem scaling) and Stage 4 (Integrated scale) to Stage 5 (Transformative & inclusive). It is derived from CMS, EMS and OES together and is non-compensatory: a core gate at Level 1 caps it at Stage 1, an unmeasured core gate or thin capability evidence suppresses it entirely, and no stage is valid until human validation. Strength in one area cannot buy off a foundational weakness in another.
A6: Core gates | B6: Core gate indicators | C6: Foundational checks | D6: Thirteen foundational indicators - such as rural connectivity, a national farmer registry and cybersecurity capability - that the model treats as prerequisites rather than as points to be traded off. Any one of them at Level 1 caps the stage at Stage 1; any one left unmeasured means no stage can be claimed at all.
A7: Stale items | B7: Stale evidence | C7: Past their vintage | D7: Levelled indicators whose observation year is older than the maximum age this model allows for them - two years for most, three for the slower-moving ones. The count spans every pillar, including the C0 context profile. Each stale item needs a refresh or a recorded exception before the read-outs can be relied on.
A8: Coverage | B8: Coverage gate | C8: Evidence sufficiency | D8: The share of a pillar's indicators that carry an assigned level. Below 60% the pillar score is suppressed instead of computed, and any composite containing that pillar is suppressed with it - so a confident-looking number is never produced from thin evidence. A separate 70% capability-coverage threshold governs whether an overall stage may be issued at all.
A9: Provisional | B9: Provisional level | C9: Machine-suggested | D9: A level the machine derived from a threshold rule, not yet confirmed by an assessor. Provisional levels do feed the scores you see - in a Step 1 pack they are the only input - which is precisely why no stage is claimable until a human sets the assessor level at Step 6 and the reading becomes validated evidence.
A10: Engagement package | B10: Engagement-package rule | C10: Pre-mandate status | D10: Everything assembled before the government mandate (Step 5) is preparatory material for a Bank decision, not an assessment of the country. No maturity stage is claimable from it, however complete the evidence looks.

Sheet Methodology
A1: Section | B1: Content
A2: purpose | B2: DAR Studio is a working prototype of the DAMM v1.3 methodology - the diagnostic that underpins a World Bank Digital Agriculture Roadmap. It assembles what public evidence can tell us about a country's digital-agriculture readiness, shows plainly what it cannot tell us, and carries a task team through the decisions that turn a diagnostic into a roadmap.
A3: not | B3: It is not an official World Bank system, not a country ranking, and not a scoring service. It produces a structured basis for professional judgement; it does not replace it. Every stage it displays is provisional until a human validates the evidence behind it.
A4: rules | B4: {"title": "Machines compute, humans gate", "text": "Everything mechanical - fetching public indicators, applying threshold rules, recomputing read-outs, drafting memo narratives - is automated. Everything consequential - whether to engage, which chains to target, what the evidence means, whether to adopt - is a human decision, recorded with the role that made it. Step 1 is the machine's own step and hands over to you when it finishes; from Step 2 onwards the ladder moves only when a human records the decision."}
A5: rules | B5: {"title": "Three read-outs, never one number", "text": "Capability, ecosystem and outcomes are reported separately and never averaged into a single index. A country can build strong systems before outcomes move, and a composite would hide exactly that gap - which is usually the finding that matters most for sequencing investment."}
A6: rules | B6: {"title": "Foundations are not tradeable", "text": "Thirteen core-gate indicators are treated as prerequisites, not as points. A core gate at Level 1 caps the overall stage regardless of strength elsewhere, because no amount of innovation activity compensates for absent rural connectivity or a missing farmer registry."}
A7: rules | B7: {"title": "Silence beats a confident guess", "text": "Where evidence is too thin, the model suppresses the score rather than computing one. A pillar below its coverage gate reads Not rated, and any composite containing it is suppressed too. An unmeasured core gate suppresses the stage entirely - so a gap can never be hidden by simply not measuring it."}
A8: rules | B8: {"title": "Evidence carries its provenance and its age", "text": "Every value records where it came from. Imported readings carry their source and observation year and are marked provisional until an assessor validates them; assessor judgements record the acting role and the time they were made. Where an observation year is present and older than this model allows for that indicator, the value is flagged stale until it is refreshed."}
A9: rules | B9: {"title": "Nothing before the mandate is an assessment", "text": "Work assembled before the government mandate is an engagement package - preparatory material for a Bank decision, not a judgement about the country. No maturity stage is claimable from it, however complete the evidence looks."}
A10: chain | B10: {"step": "Indicator", "text": "Each of the indicators carries a rubric: either numeric thresholds or a written anchor per level."}
A11: chain | B11: {"step": "Level", "text": "Evidence yields a level from 1 to 5 - machine-suggested from a threshold, or set by an assessor, who always wins. An indicator marked as a data gap contributes nothing."}
A12: chain | B12: {"step": "Pillar", "text": "A pillar score is the plain mean of the levels assigned within it - but only if enough of its indicators are levelled to clear the coverage gate."}
... A15: provenance | B15: The methodology is defined in the DAMM v1.3 draft package (Framework Specification, Operator Guide, Workbook, and a Red Team & Stress Test report that returned a conditional pass for pilot preparation). The app reads it from one versioned configuration file rather than scattering it through the code. The indicator census, rubrics, pillar weights, coverage gates and confidence weights are extracted directly from the workbook's cells; the level bands and stage thresholds are transcribed from it; and the decision ladder, the prohibitions and the wording on this page are authored in that same configuration. The non-compensatory stage cascade itself lives in the scoring engine, which is regression-tested against the Bhutan worked example - that test pins the worked example and the gate behaviours, not every possible combination.

Sheet Model outline
A1: # | B1: Title | C1: Content | D1: Produced by | E1: Ready at step | F1: Note
A2: 1 | B2: Country and sector context | C2: Agricultural structure, need and climate risk; national digital context | D2: C0 profile + M9 hazard profile + M5 imports | E2: 1 | F2: The Step 1 diagnostic assembles the context and hazard profile; the M5 prior-diagnostics imports still need steward verification at their registration gate.
A3: 2 | B3: Where the country stands | C3: CMS/EMS/OES with coverage, confidence and uncertainty; stage; pathway; momentum; solution stack; core-gate status | D3: Scoring core (v1.2.1 read-outs) | E3: 6 | F3: Provisional from Step 1, but no stage is claimable until the government mandate exists and the read-outs are validated at Step 6.
A4: 3 | B4: Vision, targeting and beneficiaries | C4: Priority value chains, regions and farmer segments; digital bind per chain; demand evidence | D4: M1 + FDUS | E4: 7 | F4: Shortlisted at Step 3 as a proposal and endorsed by government at Step 5; the regional re-projection and the farmer demand evidence arrive with the Step 7 analysis.
A5: 4 | B5: The investment program | C5: Sequenced candidates with screen results, E&S class, DPI reuse decisions, dependencies and implementation owners | D5: Screen + M6 + M7 + M10 | E5: 7 | F5: Needs validated read-outs before candidates can be screened.
A6: 5 | B6: Costs and financing | C6: Costed program under envelope scenarios; fiscal-headroom statement; instrument routing; donor consolidation plan | D6: M2 + M3 | E6: 7 | F6: The Step 7 portfolio scenario and envelope, with finance sign-off.
A7: 6 | B7: Policy and regulatory actions | C7: C3-derived reform actions routed to DPF/PforR instruments; legal drafting needs | D7: Screen + M3 | E7: 7 | F7: Built on C3 evidence validated at Step 6, then routed to instruments with the Step 7 scenario.
A8: 7 | B8: Delivery and governance | C8: Mandate and ownership matrix; steering arrangements; adoption instrument and timeline | D8: M7 + M8 | E8: 8 | F8: The mandate letter and steering committee come from the Step 5 government gates; the ownership matrix and the adoption instrument follow at Steps 7-8.
A9: 8 | B9: Climate alignment | C9: NDC/CCDR crosswalk; Paris-alignment tags; climate-finance routes | D9: M9 | E9: 7 | F9: Hazard profile arrives with the Step 1 context; financing routes follow the Step 7 scenario.
A10: 9 | B10: Results and learning | C10: Results chains with baselines; sentinel monitoring set; measurement gap register and ASA plan; evaluation strategy | D10: M4 | E10: 8 | F10: The evidence plan at Step 4 identifies the gaps; the measurement gap register is seeded from the scored census in the Step 6 evidence rounds and finalised for adoption.
A11: 10 | B11: Risks and safeguards | C11: E&S pre-screening; data rights, consent and redress; political-economy risks and mitigations; communications plan | D11: M8 + M10 + annexes | E11: 8 | F11: E&S and data-rights screening come with the Step 7 appraisal; the political-economy and communications material is assembled at Step 8.
A12: A | B12: Annexes | C12: Full indicator evidence base; dissent record; response to farmer evidence; version and configuration record | D12: Workbook + M10 + section 10 | E12: 8 | F12: The evidence base and audit trail export straight from this app.
